<?xml version="1.0"?>
<robot xmlns:xacro="http://www.ros.org/wiki/xacro">
  <xacro:property name="ptu_pan_limit" value="${170 * pi / 180}" />
  <xacro:property name="ptu_tilt_limit_upper" value="${pi / 2}" />
  <xacro:property name="ptu_tilt_limit_lower" value="${-pi / 2}" />

  <joint name="joint_ptu_deploy" type="revolute">
    <parent link="base_link"/>
    <child link="pamcam_mast"/>
    <limit effort="1000.0" lower="0" upper="${pi / 2}" velocity="0.5"/>
    <origin xyz="0.28 0 0.65" rpy="0 0 0"/>
    <axis xyz="0 -1 0"/>
    <dynamics damping="${damping}" friction="${friction}"/>
  </joint>
  
  <link name="pamcam_mast">
    <collision>
      <origin xyz="0 0 0.4" rpy="0 0 0"/>
      <geometry>
        <cylinder length="0.8" radius="0.03"/>
      </geometry>
    </collision>
    <inertial>
        <mass value="${mass}"/>
        <inertia
            ixx="${mass / 12.0 * (3 * 0.03 * 0.03 + 0.8 * 0.8)}"
            iyy="${mass / 12.0 * (3 * 0.03 * 0.03 + 0.8 * 0.8)}"
            izz="${mass / 2.0 * 0.03 * 0.03}"
            ixy="0"
            ixz="0"
            iyz="0"/>
    </inertial>
    <visual>
      <origin xyz="0 0 0.4" rpy="0 0 0"/>
      <geometry>
        <cylinder length="0.8" radius="0.03"/>
      </geometry>
      <material name="grey"/>
    </visual>
  </link>

  <joint name="joint_ptu_pan" type="revolute">
    <parent link="pamcam_mast"/>
    <child link="mast_tilt"/>
    <limit effort="1000.0" lower="${-ptu_pan_limit}" upper="${ptu_pan_limit}" velocity="0.5"/>
    <origin xyz="0 0 0.8" rpy="0 0 0"/>
    <axis xyz="0 0 1"/>
    <dynamics damping="${damping}" friction="${friction}"/>
  </joint>
  
  <link name="mast_tilt">
    <collision>
      <origin xyz="0 -0.07 0.09" rpy="0 0 0"/>
      <geometry>
        <cylinder length="0.05" radius="0.035"/>
      </geometry>
    </collision>
    <inertial>
        <mass value="${mass}"/>
        <inertia
            ixx="${mass / 12.0 * (3 * 0.035 * 0.035 + 0.05 * 0.05)}"
            iyy="${mass / 12.0 * (3 * 0.035 * 0.035 + 0.05 * 0.05)}"
            izz="${mass / 2.0 * 0.035 * 0.035}"
            ixy="0"
            ixz="0"
            iyz="0"/>
    </inertial>
    <visual>
      <origin xyz="0 -0.07 0.09" rpy="${pi / 2} 0 0"/>
      <geometry>
        <cylinder length="0.05" radius="0.035"/>
      </geometry>
      <material name="grey"/>
    </visual>
  </link>

  <joint name="joint_ptu_tilt" type="revolute">
    <parent link="mast_tilt"/>
    <child link="pancam_support"/>
    <limit effort="1000.0" lower="${ptu_tilt_limit_lower}" upper="${ptu_tilt_limit_upper}" velocity="0.5"/>
    <origin xyz="0 0 0.09" rpy="0 0 0"/>
    <axis xyz="0 1 0"/>
    <dynamics damping="${damping}" friction="${friction}"/>
  </joint>
  
  <link name="pancam_support">
    <collision>
      <origin xyz="0 0 0.2" rpy="0 0 0"/>
      <geometry>
        <box size="0.07 0.58 0.06"/>
      </geometry>
    </collision>
    <inertial>
       <mass value="${mass}"/>
        <inertia
            ixx="${mass / 12.0 * (0.58 * 0.58 + 0.06 * 0.06)}"
            iyy="${mass / 12.0 * (0.07 * 0.07 + 0.06 * 0.06)}"
            izz="${mass / 12.0 * (0.07 * 0.07 + 0.58 * 0.58)}"
            ixy="0"
            ixz="0"
            iyz="0"/>
    </inertial>
    <visual>
      <origin xyz="0 0 0.2" rpy="0 0 0"/>
      <geometry>
        <box size="0.07 0.58 0.06"/>
      </geometry>
      <material name="gold"/>
    </visual>
  </link>

  <joint name="camera_joint_left" type="fixed">
    <axis xyz="0 1 0" />
    <origin xyz="${0.035+0.01} 0.25 0.2" rpy="0 0 0"/>
    <parent link="pancam_support"/>
    <child link="pancam_frame_left"/>
  </joint>

  <link name="pancam_frame_left">
    <collision>
      <origin xyz="0 0 0" rpy="0 ${pi / 2} 0"/>
      <geometry>
        <cylinder length="0.04" radius="0.02"/>
      </geometry>
    </collision>
    <inertial>
        <mass value="0.01"/>
        <inertia
            ixx="${0.01 / 12.0 * (3 * 0.02 * 0.02 + 0.04 * 0.04)}"
            iyy="${0.01 / 12.0 * (3 * 0.02 * 0.02 + 0.04 * 0.04)}"
            izz="${0.01 / 2.0 * 0.02 * 0.02}"
            ixy="0"
            ixz="0"
            iyz="0"/>
    </inertial>
    <visual>
      <origin xyz="0 0 0" rpy="0 ${pi / 2} 0"/>
      <geometry>
        <cylinder length="0.04" radius="0.02"/>
      </geometry>
      <material name="camera"/>
    </visual>
  </link>

  <joint name="camera_joint_right" type="fixed">
    <axis xyz="0 1 0" />
    <origin xyz="${0.035+0.01} -0.25 0.2" rpy="0 0 0"/>
    <parent link="pancam_support"/>
    <child link="pancam_frame_right"/>
  </joint>

  <link name="pancam_frame_right">
    <collision>
      <origin xyz="0 0 0" rpy="0 ${pi / 2} 0"/>
      <geometry>
        <cylinder length="0.04" radius="0.02"/>
      </geometry>
    </collision>
    <inertial>
        <mass value="0.01"/>
        <inertia
            ixx="${0.01 / 12.0 * (3 * 0.02 * 0.02 + 0.04 * 0.04)}"
            iyy="${0.01 / 12.0 * (3 * 0.02 * 0.02 + 0.04 * 0.04)}"
            izz="${0.01 / 2.0 * 0.02 * 0.02}"
            ixy="0"
            ixz="0"
            iyz="0"/>
    </inertial>
    <visual>
      <origin xyz="0 0 0" rpy="0 ${pi / 2} 0"/>
      <geometry>
        <cylinder length="0.04" radius="0.02"/>
      </geometry>
      <material name="camera"/>
    </visual>
  </link>

  <joint name="camera_joint_hrc" type="fixed">
    <axis xyz="0 1 0" />
    <origin xyz="${0.035+0.01} -0.1 0.2" rpy="0 0 0"/>
    <parent link="pancam_support"/>
    <child link="pancam_frame_hrc"/>
  </joint>

  <link name="pancam_frame_hrc">
    <collision>
      <origin xyz="0 0 0" rpy="0 ${pi / 2} 0"/>
      <geometry>
        <cylinder length="0.04" radius="0.03"/>
      </geometry>
    </collision>
    <inertial>
        <mass value="0.01"/>
        <inertia
            ixx="${0.01 / 12.0 * (3 * 0.03 * 0.03 + 0.04 * 0.04)}"
            iyy="${0.01 / 12.0 * (3 * 0.03 * 0.03 + 0.04 * 0.04)}"
            izz="${0.01 / 2.0 * 0.03 * 0.03}"
            ixy="0"
            ixz="0"
            iyz="0"/>
    </inertial>
    <visual>
      <origin xyz="0 0 0" rpy="0 ${pi / 2} 0"/>
      <geometry>
        <cylinder length="0.04" radius="0.03"/>
      </geometry>
      <material name="camera"/>
    </visual>
  </link>

  <!-- Reference: https://www.liebertpub.com/doi/10.1089/ast.2016.1548 -->
  <gazebo reference="pancam_frame_left">
    <sensor type="multicamera" name="wide_angle_camera">
      <update_rate>30.0</update_rate>
      <camera name="left">
        <horizontal_fov>${38.3 * pi / 180}</horizontal_fov>
        <image>
          <width>1024</width>
          <height>1024</height>
          <format>R8G8B8</format>
        </image>
        <clip>
          <near>0.02</near>
          <far>300</far>
        </clip>
        <noise>
          <type>gaussian</type>
          <mean>0.0</mean>
          <stddev>0.007</stddev>
        </noise>
      </camera>
      <camera name="right">
        <pose>0 -0.5 0 0 0 0</pose>
        <horizontal_fov>${38.3 * pi / 180}</horizontal_fov>
        <image>
          <width>1024</width>
          <height>1024</height>
          <format>R8G8B8</format>
        </image>
        <clip>
          <near>0.02</near>
          <far>300</far>
        </clip>
        <noise>
          <type>gaussian</type>
          <mean>0.0</mean>
          <stddev>0.007</stddev>
        </noise>
      </camera>
      <plugin name="stereo_camera_controller" filename="libgazebo_ros_multicamera.so">
        <alwaysOn>true</alwaysOn>
        <updateRate>0.0</updateRate>
        <cameraName>wac</cameraName>
        <imageTopicName>image_raw</imageTopicName>
        <cameraInfoTopicName>camera_info</cameraInfoTopicName>
        <frameName>pancam_frame_left</frameName>
        <!--<rightFrameName>right_camera_optical_frame</rightFrameName>-->
        <hackBaseline>0.07</hackBaseline>
        <distortionK1>0.0</distortionK1>
        <distortionK2>0.0</distortionK2>
        <distortionK3>0.0</distortionK3>
        <distortionT1>0.0</distortionT1>
        <distortionT2>0.0</distortionT2>
      </plugin>
    </sensor>
  </gazebo>

  <!-- High Resolution Camera (HRC) -->
  <gazebo reference="pancam_frame_hrc">
    <sensor type="camera" name="high_resolution_camera">
      <update_rate>30.0</update_rate>
      <camera name="head">
        <horizontal_fov>${4.88 * pi / 180}</horizontal_fov>
        <image>
          <width>1024</width>
          <height>1024</height>
          <format>R8G8B8</format>
        </image>
        <clip>
          <near>0.02</near>
          <far>300</far>
        </clip>
        <noise>
          <type>gaussian</type>
          <mean>0.0</mean>
          <stddev>0.007</stddev>
        </noise>
      </camera>
      <plugin name="camera_controller" filename="libgazebo_ros_camera.so">
        <alwaysOn>true</alwaysOn>
        <updateRate>0.0</updateRate>
        <cameraName>hrc</cameraName>
        <imageTopicName>image_raw</imageTopicName>
        <cameraInfoTopicName>camera_info</cameraInfoTopicName>
        <frameName>camera_link</frameName>
        <hackBaseline>0.07</hackBaseline>
        <distortionK1>0.0</distortionK1>
        <distortionK2>0.0</distortionK2>
        <distortionK3>0.0</distortionK3>
        <distortionT1>0.0</distortionT1>
        <distortionT2>0.0</distortionT2>
      </plugin>
    </sensor>
  </gazebo>

  <transmission name="transmission_ptu_deploy">
    <type>transmission_interface/SimpleTransmission</type>
    <joint name="joint_ptu_deploy">
      <hardwareInterface>hardware_interface/EffortJointInterface</hardwareInterface>
    </joint>
    <actuator name="motor_ptu_deploy">
      <mechanicalReduction>1</mechanicalReduction>
    </actuator>
  </transmission>

  <transmission name="transmission_ptu_pan">
    <type>transmission_interface/SimpleTransmission</type>
    <joint name="joint_ptu_pan">
      <hardwareInterface>hardware_interface/EffortJointInterface</hardwareInterface>
    </joint>
    <actuator name="motor_ptu_pan">
      <mechanicalReduction>1</mechanicalReduction>
    </actuator>
  </transmission>

  <transmission name="transmission_ptu_tilt">
    <type>transmission_interface/SimpleTransmission</type>
    <joint name="joint_ptu_tilt">
      <hardwareInterface>hardware_interface/EffortJointInterface</hardwareInterface>
    </joint>
    <actuator name="motor_ptu_tilt">
      <mechanicalReduction>1</mechanicalReduction>
    </actuator>
  </transmission>
</robot>
